Workbook

Sheet 가이드
B2: 프리즘 BP 4.2 · QC 테스트케이스
B3: 프리즘 BP(서류평가) 4.2 | 작성일 2026-06-24 | QC 착수 2026-06-26(금) | 운영 릴리즈 2026-07-02(목) | TC 245개(결과지 147·API 42·어드민 56)
B5: ■ 테스트는 이렇게 진행됩니다 (먼저 큰 흐름부터)
B6: ① 테스트 실행 → ② 결과 기록 (Pass / Fail) → ③ 실패 시 결함·심각도 작성 → ④ 개발 수정 → ⑤ QA 재확인 QA 담당자는 ① · ② · ⑤, 개발자는 ④ 를 담당합니다. ③~⑤ 는 Fail(실패)이 났을 때만 도는 루프입니다.
B9: ■ 시작하기 — 처음이라면 이 3가지만 하면 됩니다
B10: 1) 내 담당 시트를 열고 [담당]을 본인 이름으로 필터 → 내 TC만 나옵니다(공통 일부 + 내 시나리오). 전부 볼 필요 없음.
B11: 2) 각 행을 실행한 뒤 [QC결과] 칸에서 Pass / Fail / N/A / Blocked 를 선택하고, [실행일] · [QC담당자] 를 적습니다.
B12: 3) Fail 일 때만 [결함 내용] · [심각도] 를 적습니다. 이후 개발이 고치면 다시 확인하는 흐름으로 이어집니다.
B13: ※ 1차 점검에서 채울 칸은 [QC결과] · [실행일] · [QC담당자] 3칸뿐입니다. 나머지는 결함이 났을 때만 — 처음부터 모든 칸을 채우려 하지 마세요.
B15: ■ 참고 · 우선순위 (무엇부터 보나)
B16: P1 | C16: 핵심·필수 — 릴리즈 블로커. 가장 먼저 검증
B17: P2 | C17: 중요 — P1 통과 후 검증
B18: P3 | C18: 보조·표기 — 시간 여유 시 검증
B20: ■ 참고 · 상태 값 (각 칸 드롭다운에서 선택)
B21: QC결과 | C21: Pass 통과 / Fail 실패 / N/A 해당없음 / Blocked 아직 개발 안 됨→테스트 불가(구현되면 재실행)
B22: 심각도 | C22: 치명 릴리즈 불가 / 중 주요 기능 오류 / 경 경미·표기
B23: 개발 수정상태 | C23: 미착수 / 수정중 / 수정완료 / 보류 (개발이 기입)
B24: 재확인(QC) | C24: 재확인대기 / 재확인통과 / 재오픈(수정 후에도 실패)
B26: ■ 참고 · 테스트 방식 (결과지 시트 비고의 [ ] 표시 = 무엇을 하는 테스트인지)
B27: [데이터대조] | C27: 매니저 화면 분석값과 결과지 화면의 값이 같은지 눈으로 대조
B28: [규칙계산] | C28: 정해진 규칙(점수 차이·색 분기 등)대로 나왔는지 확인
B29: [정적검사] | C29: 화면에 정해진 문구·요소가 있는지 / 없는지 확인
B30: [렌더측정] | C30: 인쇄·레이아웃이 안 깨지는지(넘침·잘림) 확인
B31: [육안] | C31: 스크린샷으로 눈으로 확인
B32: · API 시트 = API 호출 후 응답(JSON)이 기대대로인지 확인 / 어드민 시트 = 화면에서 클릭·입력 후 동작·표시 결과 확인
B34: ■ 진행 대시보드 · 시트별 (자동 집계)
B35: 시트 | C35: 전체 | D35: 미실행 | E35: Pass | F35: Fail | G35: N/A | H35: Blocked | I35: 통과율
B36: TC_결과지 | C36: =COUNTA('TC_결과지'!B2:B2000) | D36: =C36-E36-F36-G36-H36 | E36: =COUNTIF('TC_결과지'!K2:K2000,"Pass") | F36: =COUNTIF('TC_결과지'!K2:K2000,"Fail") | G36: =COUNTIF('TC_결과지'!K2:K2000,"N/A") | H36: =COUNTIF('TC_결과지'!K2:K2000,"Blocked") | I36: =IFERROR(E36/(E36+F36),"-")
B37: TC_API | C37: =COUNTA('TC_API'!B2:B2000) | D37: =C37-E37-F37-G37-H37 | E37: =COUNTIF('TC_API'!K2:K2000,"Pass") | F37: =COUNTIF('TC_API'!K2:K2000,"Fail") | G37: =COUNTIF('TC_API'!K2:K2000,"N/A") | H37: =COUNTIF('TC_API'!K2:K2000,"Blocked") | I37: =IFERROR(E37/(E37+F37),"-")
B38: TC_어드민 | C38: =COUNTA('TC_어드민'!B2:B2000) | D38: =C38-E38-F38-G38-H38 | E38: =COUNTIF('TC_어드민'!K2:K2000,"Pass") | F38: =COUNTIF('TC_어드민'!K2:K2000,"Fail") | G38: =COUNTIF('TC_어드민'!K2:K2000,"N/A") | H38: =COUNTIF('TC_어드민'!K2:K2000,"Blocked") | I38: =IFERROR(E38/(E38+F38),"-")
B39: 합계 | C39: =SUM(C36:C38) | D39: =SUM(D36:D38) | E39: =SUM(E36:E38) | F39: =SUM(F36:F38) | G39: =SUM(G36:G38) | H39: =SUM(H36:H38) | I39: =IFERROR(E39/(E39+F39),"-")
B41: ■ 진행 대시보드 · 우선순위별 (자동 집계)
B42: 우선순위 | C42: 전체 | D42: 미실행 | E42: Pass | F42: Fail | G42: N/A | H42: Blocked | I42: 통과율
B43: P1 | C43: =COUNTIF('TC_결과지'!E2:E2000,"P1")+COUNTIF('TC_API'!E2:E2000,"P1")+COUNTIF('TC_어드민'!E2:E2000,"P1") | D43: =C43-E43-F43-G43-H43 | E43: =COUNTIFS('TC_결과지'!E2:E2000,"P1",'TC_결과지'!K2:K2000,"Pass")+COUNTIFS('TC_API'!E2:E2000,"P1",'TC_API'!K2:K2000,"Pass")+COUNTIFS('TC_어드민'!E2:E2000,"P1",'TC_어드민'!K2:K2000,"Pass") | F43: =COUNTIFS('TC_결과지'!E2:E2000,"P1",'TC_결과지'!K2:K2000,"Fail")+COUNTIFS('TC_API'!E2:E2000,"P1",'TC_API'!K2:K2000,"Fail")+COUNTIFS('TC_어드민'!E2:E2000,"P1",'TC_어드민'!K2:K2000,"Fail") | G43: =COUNTIFS('TC_결과지'!E2:E2000,"P1",'TC_결과지'!K2:K2000,"N/A")+COUNTIFS('TC_API'!E2:E2000,"P1",'TC_API'!K2:K2000,"N/A")+COUNTIFS('TC_어드민'!E2:E2000,"P1",'TC_어드민'!K2:K2000,"N/A") | H43: =COUNTIFS('TC_결과지'!E2:E2000,"P1",'TC_결과지'!K2:K2000,"Blocked")+COUNTIFS('TC_API'!E2:E2000,"P1",'TC_API'!K2:K2000,"Blocked")+COUNTIFS('TC_어드민'!E2:E2000,"P1",'TC_어드민'!K2:K2000,"Blocked") | I43: =IFERROR(E43/(E43+F43),"-")
B44: P2 | C44: =COUNTIF('TC_결과지'!E2:E2000,"P2")+COUNTIF('TC_API'!E2:E2000,"P2")+COUNTIF('TC_어드민'!E2:E2000,"P2") | D44: =C44-E44-F44-G44-H44 | E44: =COUNTIFS('TC_결과지'!E2:E2000,"P2",'TC_결과지'!K2:K2000,"Pass")+COUNTIFS('TC_API'!E2:E2000,"P2",'TC_API'!K2:K2000,"Pass")+COUNTIFS('TC_어드민'!E2:E2000,"P2",'TC_어드민'!K2:K2000,"Pass") | F44: =COUNTIFS('TC_결과지'!E2:E2000,"P2",'TC_결과지'!K2:K2000,"Fail")+COUNTIFS('TC_API'!E2:E2000,"P2",'TC_API'!K2:K2000,"Fail")+COUNTIFS('TC_어드민'!E2:E2000,"P2",'TC_어드민'!K2:K2000,"Fail") | G44: =COUNTIFS('TC_결과지'!E2:E2000,"P2",'TC_결과지'!K2:K2000,"N/A")+COUNTIFS('TC_API'!E2:E2000,"P2",'TC_API'!K2:K2000,"N/A")+COUNTIFS('TC_어드민'!E2:E2000,"P2",'TC_어드민'!K2:K2000,"N/A") | H44: =COUNTIFS('TC_결과지'!E2:E2000,"P2",'TC_결과지'!K2:K2000,"Blocked")+COUNTIFS('TC_API'!E2:E2000,"P2",'TC_API'!K2:K2000,"Blocked")+COUNTIFS('TC_어드민'!E2:E2000,"P2",'TC_어드민'!K2:K2000,"Blocked") | I44: =IFERROR(E44/(E44+F44),"-")
B45: P3 | C45: =COUNTIF('TC_결과지'!E2:E2000,"P3")+COUNTIF('TC_API'!E2:E2000,"P3")+COUNTIF('TC_어드민'!E2:E2000,"P3") | D45: =C45-E45-F45-G45-H45 | E45: =COUNTIFS('TC_결과지'!E2:E2000,"P3",'TC_결과지'!K2:K2000,"Pass")+COUNTIFS('TC_API'!E2:E2000,"P3",'TC_API'!K2:K2000,"Pass")+COUNTIFS('TC_어드민'!E2:E2000,"P3",'TC_어드민'!K2:K2000,"Pass") | F45: =COUNTIFS('TC_결과지'!E2:E2000,"P3",'TC_결과지'!K2:K2000,"Fail")+COUNTIFS('TC_API'!E2:E2000,"P3",'TC_API'!K2:K2000,"Fail")+COUNTIFS('TC_어드민'!E2:E2000,"P3",'TC_어드민'!K2:K2000,"Fail") | G45: =COUNTIFS('TC_결과지'!E2:E2000,"P3",'TC_결과지'!K2:K2000,"N/A")+COUNTIFS('TC_API'!E2:E2000,"P3",'TC_API'!K2:K2000,"N/A")+COUNTIFS('TC_어드민'!E2:E2000,"P3",'TC_어드민'!K2:K2000,"N/A") | H45: =COUNTIFS('TC_결과지'!E2:E2000,"P3",'TC_결과지'!K2:K2000,"Blocked")+COUNTIFS('TC_API'!E2:E2000,"P3",'TC_API'!K2:K2000,"Blocked")+COUNTIFS('TC_어드민'!E2:E2000,"P3",'TC_어드민'!K2:K2000,"Blocked") | I45: =IFERROR(E45/(E45+F45),"-")
B46: ※ P1 통과율이 7/02 릴리즈 가능 여부를 보는 핵심 지표입니다 (P1 전부 Pass + 치명 결함 0 → 릴리즈).
B48: ■ 결함 현황 (자동 집계)
B49: 심각도 | C49: 건수 | E49: 개발 상태 | F49: 건수
B50: 치명 | C50: =COUNTIF('TC_결과지'!O2:O2000,"치명")+COUNTIF('TC_API'!O2:O2000,"치명")+COUNTIF('TC_어드민'!O2:O2000,"치명") | E50: 미착수 | F50: =COUNTIF('TC_결과지'!P2:P2000,"미착수")+COUNTIF('TC_API'!P2:P2000,"미착수")+COUNTIF('TC_어드민'!P2:P2000,"미착수")
...

Sheet 구현현황
A1: 개발 구현현황 — 개발자 기입용 (주요 변경사항 SDS 기준)
A2: 각 기능의 '구현 상태'를 됨/되는중/안됨으로 표시해 주세요. 이 표로 QC의 P1/Blocked를 확정합니다.
A4: 번호 | B4: 구분 | C4: 변경 기능 | D4: 관련 SDS | E4: 구현 상태 | F4: 예상 완료일 | G4: 비고
A5: 1 | B5: 접수 | C5: 전형 통과 기준 '배수 기준' 단일화(점수 기준 제거)·사용여부 라디오 제거·별도 영역 분리(직무기술서 위) · 비교군 10명 미만 상위% 안내문 | D5: 프리즘 접수 화면 기능 개발
A6: 2 | B6: 접수 | C6: BP 버전 v2 라디오 제거(v3/v4만)·v3 선택 시 직무기술서 영역 미출력 | D6: 프리즘 접수 화면 기능 개발
A7: 3 | B7: 접수 | C7: 직무기술서 업로드(필수·테이블 UI·3MB/10MB·중복불가·선택해제 시 소실, RP매칭과 공유) | D7: 프리즘 접수 화면 기능 개발
A8: 4 | B8: 접수 | C8: RP매칭 부적격 기준 UI 변경(사용안함 라디오 제거·'점수 기준' 단일 체크박스, '점미만'·'부적격' 유지) | D8: 프리즘 접수 화면 기능 개발
A9: 5 | B9: 접수 | C9: 검사요청 확인 화면에 직무기술서 표현 | D9: 검사 요청 확인 직무기술서 표현
A10: 6 | B10: 매니저 | C10: 하드스킬 키워드 관리(문장형식 제거→텍스트형식, 생성/재생성/삭제/추가) | D10: 직무기술서 관리 하드스킬 키워드
A11: 7 | B11: 매니저 | C11: BP평가 결과확인 — 한 줄 코멘트 관리 | D11: BP평가 결과확인 기능 추가
A12: 8 | B12: 매니저 | C12: BP평가 결과확인 — 자소서 특장점 관리 | D12: BP평가 결과확인 기능 추가
A13: 9 | B13: 매니저 | C13: BP평가 결과확인 — 근거요약 관리 | D13: BP평가 결과확인 기능 추가
A14: 10 | B14: 매니저 | C14: BP평가 결과확인 — 하드스킬 근거문장 관리 | D14: BP평가 결과확인 기능 추가
A15: 11 | B15: 매니저 | C15: BP평가 설정 — 직무기술서 설정(직무별) | D15: BP평가 설정 직무기술서
A16: 12 | B16: API | C16: 한 줄 코멘트 생성 API (bp-v4-comment) | D16: 한 줄 코멘트 생성 API
... A25: 21 | B25: 다운로드 | C25: 엑셀 결과지 변경(전형통과 텍스트·하드스킬 검출) | D25: 엑셀파일 결과지 변경

Sheet 시나리오
A1: 테스트 시나리오 — 옵션(라이선스 × 전형통과 × 통합본문) 조합 + 작업자 분배·진행
A2: 담당자 이름은 이 시트 [담당](G)열에서만 관리 → TC 3종 [담당]이 INDEX/MATCH로 같은 이름을 자동으로 가져옴. 분배/완료는 작업자N 키(L열 ↔ TC 키열)로 자동 집계.
A3: ※ 담당자 이름은 이 시트 [담당](G)열에서만 수정하세요 → TC 3종 [담당]이 자동으로 같은 이름을 가져옵니다. (분배/완료는 G 이름이 아니라 L열 작업자N 키로 집계)
A4: 시나리오 | B4: 라이선스 조합 | C4: 전형통과 기준 | D4: 통합본문 | E4: 샘플 자소서 | F4: 적용 TC(주) | G4: 담당 | H4: 분배 | I4: 완료 | J4: 남은 | K4: 상태 | L4: 키(작업자)
A5: SC-1 단독·배수권장 | B5: BP 단독 | C5: 배수기준 → 권장(이내) | D5: OFF | E5: B 정수민 | F5: 단독 구성(W1·Q1·Q2) · 배수기준 권장칩(S3·E) · 통합본문 OFF=개별본문(X3) | G5: 조아영 | H5: =COUNTIF('TC_결과지'!$T$2:$T$2000,$L5)+COUNTIF('TC_API'!$T$2:$T$2000,$L5)+COUNTIF('TC_어드민'!$T$2:$T$2000,$L5) | I5: =COUNTIFS('TC_결과지'!$T$2:$T$2000,$L5,'TC_결과지'!$K$2:$K$2000,"<>")+COUNTIFS('TC_API'!$T$2:$T$2000,$L5,'TC_API'!$K$2:$K$2000,"<>")+COUNTIFS('TC_어드민'!$T$2:$T$2000,$L5,'TC_어드민'!$K$2:$K$2000,"<>") | J5: =H5-I5 | L5: 작업자1
A6: SC-2 단독·배수검토필요 | B6: BP 단독 | C6: 배수기준 → 검토 필요(미달) | D6: OFF | E6: C 김도윤 | F6: 단독 구성(W1) · 배수기준 검토필요 주황칩(S3·E4) | G6: 기효선1 | H6: =COUNTIF('TC_결과지'!$T$2:$T$2000,$L6)+COUNTIF('TC_API'!$T$2:$T$2000,$L6)+COUNTIF('TC_어드민'!$T$2:$T$2000,$L6) | I6: =COUNTIFS('TC_결과지'!$T$2:$T$2000,$L6,'TC_결과지'!$K$2:$K$2000,"<>")+COUNTIFS('TC_API'!$T$2:$T$2000,$L6,'TC_API'!$K$2:$K$2000,"<>")+COUNTIFS('TC_어드민'!$T$2:$T$2000,$L6,'TC_어드민'!$K$2:$K$2000,"<>") | J6: =H6-I6 | L6: 작업자2
A7: SC-3 단독·통과기준 미사용 | B7: BP 단독 | C7: 사용 안 함(배수 미체크) | D7: OFF | E7: A 홍길동 | F7: 단독 구성(W1) · 전형통과 미표기(S5) · 비교군 10명 미만 상위% 미출력(E8) | G7: 김재현 | H7: =COUNTIF('TC_결과지'!$T$2:$T$2000,$L7)+COUNTIF('TC_API'!$T$2:$T$2000,$L7)+COUNTIF('TC_어드민'!$T$2:$T$2000,$L7) | I7: =COUNTIFS('TC_결과지'!$T$2:$T$2000,$L7,'TC_결과지'!$K$2:$K$2000,"<>")+COUNTIFS('TC_API'!$T$2:$T$2000,$L7,'TC_API'!$K$2:$K$2000,"<>")+COUNTIFS('TC_어드민'!$T$2:$T$2000,$L7,'TC_어드민'!$K$2:$K$2000,"<>") | J7: =H7-I7 | L7: 작업자3
A8: SC-4 복수·통합본문 | B8: BP+표절+블라인드 | C8: 점수기준 | D8: ON | E8: A 홍길동 | F8: 복수 종합결과 구성(W3·Q3~Q7) · 종합결과 칩(E7) · 통합본문 ON+개별본문 제거(X1·X2) | G8: 기효선2 | H8: =COUNTIF('TC_결과지'!$T$2:$T$2000,$L8)+COUNTIF('TC_API'!$T$2:$T$2000,$L8)+COUNTIF('TC_어드민'!$T$2:$T$2000,$L8) | I8: =COUNTIFS('TC_결과지'!$T$2:$T$2000,$L8,'TC_결과지'!$K$2:$K$2000,"<>")+COUNTIFS('TC_API'!$T$2:$T$2000,$L8,'TC_API'!$K$2:$K$2000,"<>")+COUNTIFS('TC_어드민'!$T$2:$T$2000,$L8,'TC_어드민'!$K$2:$K$2000,"<>") | J8: =H8-I8 | L8: 작업자4
A9: SC-5 전체·통합본문 | B9: 전체 8종 | C9: 배수기준 | D9: ON | E9: A 홍길동 | F9: 전체 8종 종합결과 1p 이내(W9) · 통합본문 다중 하이라이트(X5) | G9: 최고운 | H9: =COUNTIF('TC_결과지'!$T$2:$T$2000,$L9)+COUNTIF('TC_API'!$T$2:$T$2000,$L9)+COUNTIF('TC_어드민'!$T$2:$T$2000,$L9) | I9: =COUNTIFS('TC_결과지'!$T$2:$T$2000,$L9,'TC_결과지'!$K$2:$K$2000,"<>")+COUNTIFS('TC_API'!$T$2:$T$2000,$L9,'TC_API'!$K$2:$K$2000,"<>")+COUNTIFS('TC_어드민'!$T$2:$T$2000,$L9,'TC_어드민'!$K$2:$K$2000,"<>") | J9: =H9-I9 | L9: 작업자5
A10: SC-6 전형통과 미사용 | B10: BP+GPK | C10: 사용 안 함 | D10: OFF | E10: A 홍길동 | F10: 전형통과 미표기(S5) · GPK-BP 연동·과금(W4·T) | G10: 전예원 | H10: =COUNTIF('TC_결과지'!$T$2:$T$2000,$L10)+COUNTIF('TC_API'!$T$2:$T$2000,$L10)+COUNTIF('TC_어드민'!$T$2:$T$2000,$L10) | I10: =COUNTIFS('TC_결과지'!$T$2:$T$2000,$L10,'TC_결과지'!$K$2:$K$2000,"<>")+COUNTIFS('TC_API'!$T$2:$T$2000,$L10,'TC_API'!$K$2:$K$2000,"<>")+COUNTIFS('TC_어드민'!$T$2:$T$2000,$L10,'TC_어드민'!$K$2:$K$2000,"<>") | J10: =H10-I10 | L10: 작업자6
A11: SC-7 비-BP·통합본문 | B11: 결함+표절 | C11: 해당 없음 | D11: ON | E11: A 홍길동 | F11: BP 없는 복수(W5) · 통합본문 ON(X1) | G11: 윤경은 | H11: =COUNTIF('TC_결과지'!$T$2:$T$2000,$L11)+COUNTIF('TC_API'!$T$2:$T$2000,$L11)+COUNTIF('TC_어드민'!$T$2:$T$2000,$L11) | I11: =COUNTIFS('TC_결과지'!$T$2:$T$2000,$L11,'TC_결과지'!$K$2:$K$2000,"<>")+COUNTIFS('TC_API'!$T$2:$T$2000,$L11,'TC_API'!$K$2:$K$2000,"<>")+COUNTIFS('TC_어드민'!$T$2:$T$2000,$L11,'TC_어드민'!$K$2:$K$2000,"<>") | J11: =H11-I11 | L11: 작업자7
G12: 합계 | H12: =SUM(H5:H11) | I12: =SUM(I5:I11) | J12: =SUM(J5:J11)
A14: ※ 검수자: 본인 시트에서 [담당]을 본인 이름으로 필터 → 내 TC만(공통 일부 + 내 시나리오). [구분]으로 공통/시나리오 구분.
A15: ※ 분배 합계 = 245(전 TC 배정). 완료 = QC결과 입력된 행. 담당자가 바뀌면 이 시트 [담당](G)열 이름만 수정 → TC 3종 [담당] 자동 반영(분배/완료는 작업자N 키로 집계되어 영향 없음).

Sheet TC_결과지
A1: 담당 | B1: TC ID | C1: 대분류 | D1: 중분류 | E1: 우선 순위 | F1: 테스트 시나리오(케이스명) | G1: 사전조건 | H1: 테스트 절차 | I1: 입력/조건 | J1: 기대결과 | K1: QC결과 | L1: 실행일 | M1: QC담당자 | N1: 결함 내용 | O1: 심각도 | P1: 개발 수정상태 | Q1: 재확인(QC) | R1: 비고 | S1: 구분 | T1: 키(작업자)
A2: =IFERROR(INDEX('시나리오'!$G$5:$G$11,MATCH($T2,'시나리오'!$L$5:$L$11,0)),$T2) | B2: RPT-001 | C2: 결과지(출력물) | D2: A. 빌드 무결성 | E2: P1 | F2: A1 미치환 토큰 0건 | G2: 샘플 자소서가 접수→분석→결과지까지 완료(매니저 화면에 분석값 확인 가능) | H2: HTML 텍스트·구조를 regex/DOM 카운트로 검사 | I2: - | J2: HTML 본문에 {{...}} 패턴(미치환 토큰)이 1건도 남아있지 않다. regex \{\{[A-Z_]+\}\} → 0건 | R2: [정적검사] | S2: 공통 | T2: 작업자1
A3: =IFERROR(INDEX('시나리오'!$G$5:$G$11,MATCH($T3,'시나리오'!$L$5:$L$11,0)),$T3) | B3: RPT-002 | C3: 결과지(출력물) | D3: A. 빌드 무결성 | E3: P2 | F3: A2 다운로드 PDF 파일명 규칙 | G3: 샘플 자소서가 접수→분석→결과지까지 완료(매니저 화면에 분석값 확인 가능) | H3: HTML 텍스트·구조를 regex/DOM 카운트로 검사 | I3: - | J3: 프리즘워크에서 다운로드한 PDF 파일명이 정해진 규칙([제품]-[지원자명]-[날짜])과 일치 | R3: [정적검사] | S3: 공통 | T3: 작업자2
A4: =IFERROR(INDEX('시나리오'!$G$5:$G$11,MATCH($T4,'시나리오'!$L$5:$L$11,0)),$T4) | B4: RPT-003 | C4: 결과지(출력물) | D4: B. 메타·식별 | E4: P1 | F4: B1 채용공고명 일치 | G4: 샘플 자소서가 접수→분석→결과지까지 완료(매니저 화면에 분석값 확인 가능) | H4: 매니저 화면 분석값과 결과지 노출값을 글자·자릿수 단위로 대조 | I4: 3단계 분석값(매니저 결과확인 화면) | J4: meta.channel_title이 doc-header(.doc-header-title, 전 페이지)와 블루헤더(.bp-header-title) 두 위치에서 동일 | R4: [데이터대조] | S4: 공통 | T4: 작업자3
A5: =IFERROR(INDEX('시나리오'!$G$5:$G$11,MATCH($T5,'시나리오'!$L$5:$L$11,0)),$T5) | B5: RPT-004 | C5: 결과지(출력물) | D5: B. 메타·식별 | E5: P1 | F5: B2 지원자명 일치 | G5: 샘플 자소서가 접수→분석→결과지까지 완료(매니저 화면에 분석값 확인 가능) | H5: 매니저 화면 분석값과 결과지 노출값을 글자·자릿수 단위로 대조 | I5: 3단계 분석값(매니저 결과확인 화면) | J5: meta.candidate가 doc-header(.doc-header-name)·카드(.bp-prof-name)·<title> 3위치에서 동일 | R5: [데이터대조] | S5: 공통 | T5: 작업자4
A6: =IFERROR(INDEX('시나리오'!$G$5:$G$11,MATCH($T6,'시나리오'!$L$5:$L$11,0)),$T6) | B6: RPT-005 | C6: 결과지(출력물) | D6: B. 메타·식별 | E6: P1 | F6: B3 응시번호 일치 | G6: 샘플 자소서가 접수→분석→결과지까지 완료(매니저 화면에 분석값 확인 가능) | H6: 매니저 화면 분석값과 결과지 노출값을 글자·자릿수 단위로 대조 | I6: 3단계 분석값(매니저 결과확인 화면) | J6: meta.candidate_number가 doc-header(.doc-header-num)·카드(.bp-prof-num) 일치 | R6: [데이터대조] | S6: 공통 | T6: 작업자5
A7: =IFERROR(INDEX('시나리오'!$G$5:$G$11,MATCH($T7,'시나리오'!$L$5:$L$11,0)),$T7) | B7: RPT-006 | C7: 결과지(출력물) | D7: B. 메타·식별 | E7: P2 | F7: B4 직무명 | G7: 샘플 자소서가 접수→분석→결과지까지 완료(매니저 화면에 분석값 확인 가능) | H7: 매니저 화면 분석값과 결과지 노출값을 글자·자릿수 단위로 대조 | I7: 3단계 분석값(매니저 결과확인 화면) | J7: meta.position이 카드 .bp-prof-job와 일치 | R7: [데이터대조] | S7: 공통 | T7: 작업자6
A8: =IFERROR(INDEX('시나리오'!$G$5:$G$11,MATCH($T8,'시나리오'!$L$5:$L$11,0)),$T8) | B8: RPT-007 | C8: 결과지(출력물) | D8: B. 메타·식별 | E8: P2 | F8: B5 평가일 | G8: 샘플 자소서가 접수→분석→결과지까지 완료(매니저 화면에 분석값 확인 가능) | H8: 매니저 화면 분석값과 결과지 노출값을 글자·자릿수 단위로 대조 | I8: 3단계 분석값(매니저 결과확인 화면) | J8: meta.evaluation_date가 카드 .bp-date와 일치('평가일: ' 접두 포함) | R8: [데이터대조] | S8: 공통 | T8: 작업자7
A9: =IFERROR(INDEX('시나리오'!$G$5:$G$11,MATCH($T9,'시나리오'!$L$5:$L$11,0)),$T9) | B9: RPT-008 | C9: 결과지(출력물) | D9: B. 메타·식별 | E9: P1 | F9: B6 doc-header 전 페이지 동일 | G9: 샘플 자소서가 접수→분석→결과지까지 완료(매니저 화면에 분석값 확인 가능) | H9: HTML 텍스트·구조를 regex/DOM 카운트로 검사 | I9: - | J9: 모든 페이지 doc-header의 B1~B3 값이 동일(한 페이지라도 다르면 실패) | R9: [정적검사] | S9: 공통 | T9: 작업자1
A10: =IFERROR(INDEX('시나리오'!$G$5:$G$11,MATCH($T10,'시나리오'!$L$5:$L$11,0)),$T10) | B10: RPT-009 | C10: 결과지(출력물) | D10: C. 점수 정확성 | E10: P1 | F10: C1 종합점수 4곳 동일 | G10: 샘플 자소서가 접수→분석→결과지까지 완료(매니저 화면에 분석값 확인 가능) | H10: 매니저 화면 분석값과 결과지 노출값을 글자·자릿수 단위로 대조 | I10: 3단계 분석값(매니저 결과확인 화면) | J10: scores.total이 카드 .bp-score-num·요약 .summary-pos-score·요약막대 .cbar-fill width(%)에서 동일 | R10: [데이터대조] | S10: 공통 | T10: 작업자2
A11: =IFERROR(INDEX('시나리오'!$G$5:$G$11,MATCH($T11,'시나리오'!$L$5:$L$11,0)),$T11) | B11: RPT-010 | C11: 결과지(출력물) | D11: C. 점수 정확성 | E11: P1 | F11: C2 직무적합도 | G11: 샘플 자소서가 접수→분석→결과지까지 완료(매니저 화면에 분석값 확인 가능) | H11: 매니저 화면 분석값과 결과지 노출값을 글자·자릿수 단위로 대조 | I11: 3단계 분석값(매니저 결과확인 화면) | J11: scores.직무적합도가 P1 .jma .metric-score·P4+ dt-cat '직무적합도 …점'에서 일치 | R11: [데이터대조] | S11: 공통 | T11: 작업자3
A12: =IFERROR(INDEX('시나리오'!$G$5:$G$11,MATCH($T12,'시나리오'!$L$5:$L$11,0)),$T12) | B12: RPT-011 | C12: 결과지(출력물) | D12: C. 점수 정확성 | E12: P1 | F12: C3 조직적합도 | G12: 샘플 자소서가 접수→분석→결과지까지 완료(매니저 화면에 분석값 확인 가능) | H12: 매니저 화면 분석값과 결과지 노출값을 글자·자릿수 단위로 대조 | I12: 3단계 분석값(매니저 결과확인 화면) | J12: scores.조직적합도가 P1 조직카드 .metric-score·P4+ dt-cat에서 일치 | R12: [데이터대조] | S12: 공통 | T12: 작업자4
A13: =IFERROR(INDEX('시나리오'!$G$5:$G$11,MATCH($T13,'시나리오'!$L$5:$L$11,0)),$T13) | B13: RPT-012 | C13: 결과지(출력물) | D13: C. 점수 정확성 | E13: P1 | F13: C4 지원동기 | G13: 샘플 자소서가 접수→분석→결과지까지 완료(매니저 화면에 분석값 확인 가능) | H13: 매니저 화면 분석값과 결과지 노출값을 글자·자릿수 단위로 대조 | I13: 3단계 분석값(매니저 결과확인 화면) | J13: scores.지원동기가 P1 지원동기카드·P4+ dt-cat에서 일치 | R13: [데이터대조] | S13: 공통 | T13: 작업자5
... A148: =IFERROR(INDEX('시나리오'!$G$5:$G$11,MATCH($T148,'시나리오'!$L$5:$L$11,0)),$T148) | B148: RPT-147 | C148: 결과지(출력물) | D148: X. 통합본문 | E148: P2 | F148: X5 다중 하이라이트 구분 | G148: 샘플 자소서가 접수→분석→결과지까지 완료(매니저 화면에 분석값 확인 가능) | H148: 스크린샷으로 육안 확인(필요 시 diff) | I148: - | J148: 여러 라이선스 하이라이트가 한 본문에 공존 시 색·표시가 라이선스별로 구분되고 겹침/누락 없이 렌더 | R148: [육안] | S148: 시나리오 | T148: 작업자5

Sheet TC_API
A1: 담당 | B1: TC ID | C1: 대분류 | D1: 중분류 | E1: 우선 순위 | F1: 테스트 시나리오(케이스명) | G1: 사전조건 | H1: 테스트 절차 | I1: 입력/조건 | J1: 기대결과 | K1: QC결과 | L1: 실행일 | M1: QC담당자 | N1: 결함 내용 | O1: 심각도 | P1: 개발 수정상태 | Q1: 재확인(QC) | R1: 비고 | S1: 구분 | T1: 키(작업자)
A2: =IFERROR(INDEX('시나리오'!$G$5:$G$11,MATCH($T2,'시나리오'!$L$5:$L$11,0)),$T2) | B2: API-001 | C2: API | D2: ① 한 줄 코멘트 | E2: P1 | F2: 정상 생성(happy path) | G2: execute API·공방 프롬프트(bp-v4-comment) 배포 · API PRISM/GENERATE-BP-COMMENT · llmServiceKey 발급 | H2: POST /common/prompt-execute 호출 | I2: 강점2+검토1~2 factor digest, max_chars="90" | J2: status=ok, result.one_liner 1문장, parts.strength/weakness/action 3요소 모두 채워짐, meta.grounded=true | S2: 공통 | T2: 작업자3
A3: =IFERROR(INDEX('시나리오'!$G$5:$G$11,MATCH($T3,'시나리오'!$L$5:$L$11,0)),$T3) | B3: API-002 | C3: API | D3: ① 한 줄 코멘트 | E3: P1 | F3: 두괄식(강점 선두) | G3: execute API·공방 프롬프트(bp-v4-comment) 배포 · API PRISM/GENERATE-BP-COMMENT · llmServiceKey 발급 | H3: 응답 one_liner 문장 구조 확인 | I3: 정상 digest | J3: 한 문장이 강점→단점→액션 순서, 강점이 문장 맨 앞 | S3: 공통 | T3: 작업자4
A4: =IFERROR(INDEX('시나리오'!$G$5:$G$11,MATCH($T4,'시나리오'!$L$5:$L$11,0)),$T4) | B4: API-003 | C4: API | D4: ① 한 줄 코멘트 | E4: P1 | F4: 금지어 미사용 | G4: execute API·공방 프롬프트(bp-v4-comment) 배포 · API PRISM/GENERATE-BP-COMMENT · llmServiceKey 발급 | H4: one_liner·parts에 금지어 포함 검사 | I4: 정상 digest | J4: '합격/불합격/적격/부적격/탈락' 미포함('권장/검토 필요/확인'으로 표현) | R4: hard fail | S4: 공통 | T4: 작업자5
A5: =IFERROR(INDEX('시나리오'!$G$5:$G$11,MATCH($T5,'시나리오'!$L$5:$L$11,0)),$T5) | B5: API-004 | C5: API | D5: ① 한 줄 코멘트 | E5: P1 | F5: 무근거 금지/grounded | G5: execute API·공방 프롬프트(bp-v4-comment) 배포 · API PRISM/GENERATE-BP-COMMENT · llmServiceKey 발급 | H5: 입력에 없는 영역·등급 등장 검사 | I5: grade=none factor 포함 digest | J5: none 역량을 강점으로 단정 안 함, 입력에 없는 사실 미생성, meta.grounded=true | R5: hard fail | S5: 공통 | T5: 작업자6
A6: =IFERROR(INDEX('시나리오'!$G$5:$G$11,MATCH($T6,'시나리오'!$L$5:$L$11,0)),$T6) | B6: API-005 | C6: API | D6: ① 한 줄 코멘트 | E6: P1 | F6: 길이 제한 | G6: execute API·공방 프롬프트(bp-v4-comment) 배포 · API PRISM/GENERATE-BP-COMMENT · llmServiceKey 발급 | H6: one_liner 실제 글자수 확인 | I6: max_chars=90 | J6: one_liner 글자수 ≤ 90(초과 시 비교수치→수식어 순 축소) | S6: 공통 | T6: 작업자7
A7: =IFERROR(INDEX('시나리오'!$G$5:$G$11,MATCH($T7,'시나리오'!$L$5:$L$11,0)),$T7) | B7: API-006 | C7: API | D7: ① 한 줄 코멘트 | E7: P2 | F7: 3요소 누락 시 재생성 | G7: execute API·공방 프롬프트(bp-v4-comment) 배포 · API PRISM/GENERATE-BP-COMMENT · llmServiceKey 발급 | H7: parts 각 필드 확인 | I7: 강점/검토 일부만 있는 digest | J7: parts.strength/weakness/action 중 빈 값 없음 | S7: 공통 | T7: 작업자1
A8: =IFERROR(INDEX('시나리오'!$G$5:$G$11,MATCH($T8,'시나리오'!$L$5:$L$11,0)),$T8) | B8: API-007 | C8: API | D8: ① 한 줄 코멘트 | E8: P2 | F8: 검토 메트릭 롤업 | G8: execute API·공방 프롬프트(bp-v4-comment) 배포 · API PRISM/GENERATE-BP-COMMENT · llmServiceKey 발급 | H8: digest factors의 level 확인 | I8: 같은 메트릭 none factor 2개+ | J8: 검토가 level=metric 1개로 롤업('(메트릭) 전반 근거 확인 안 됨' 서술) | S8: 공통 | T8: 작업자2
A9: =IFERROR(INDEX('시나리오'!$G$5:$G$11,MATCH($T9,'시나리오'!$L$5:$L$11,0)),$T9) | B9: API-008 | C9: API | D9: ① 한 줄 코멘트 | E9: P1 | F9: standing 수치 미출력 | G9: execute API·공방 프롬프트(bp-v4-comment) 배포 · API PRISM/GENERATE-BP-COMMENT · llmServiceKey 발급 | H9: one_liner에 숫자 단정 여부 확인 | I9: total_score·percentile_top 포함 | J9: 상위%·총점 수치가 문장에 단정 출력되지 않음(어조 판단에만 사용) | S9: 공통 | T9: 작업자3
A10: =IFERROR(INDEX('시나리오'!$G$5:$G$11,MATCH($T10,'시나리오'!$L$5:$L$11,0)),$T10) | B10: API-009 | C10: API | D10: ① 한 줄 코멘트 | E10: P2 | F10: 강점이 high 아닐 때 완화 | G10: execute API·공방 프롬프트(bp-v4-comment) 배포 · API PRISM/GENERATE-BP-COMMENT · llmServiceKey 발급 | H10: one_liner 서술 톤 확인 | I10: 상위2 factor grade=mid | J10: '상대적으로 두드러진' 식 완화 서술(단정 강점 아님) | S10: 공통 | T10: 작업자4
A11: =IFERROR(INDEX('시나리오'!$G$5:$G$11,MATCH($T11,'시나리오'!$L$5:$L$11,0)),$T11) | B11: API-010 | C11: API | D11: ① 한 줄 코멘트 | E11: P2 | F11: 출력 스키마 Strict | G11: execute API·공방 프롬프트(bp-v4-comment) 배포 · API PRISM/GENERATE-BP-COMMENT · llmServiceKey 발급 | H11: result 구조 검증 | I11: 정상 호출 | J11: required(one_liner·char_count·parts·meta) 전부 존재, additionalProperties 없음 | S11: 공통 | T11: 작업자5
A12: =IFERROR(INDEX('시나리오'!$G$5:$G$11,MATCH($T12,'시나리오'!$L$5:$L$11,0)),$T12) | B12: API-011 | C12: API | D12: ① 한 줄 코멘트 | E12: P2 | F12: 변수 누락 감지 | G12: execute API·공방 프롬프트(bp-v4-comment) 배포 · API PRISM/GENERATE-BP-COMMENT · llmServiceKey 발급 | H12: config.onMissingVariables=error로 호출 | I12: keyValue에서 max_chars 누락 | J12: status=fail + 변수 누락 message(빈 문자열 대체 아님) | S12: 공통 | T12: 작업자6
A13: =IFERROR(INDEX('시나리오'!$G$5:$G$11,MATCH($T13,'시나리오'!$L$5:$L$11,0)),$T13) | B13: API-012 | C13: API | D13: ① 한 줄 코멘트 | E13: P3 | F13: char_count 부정확 주의 | G13: execute API·공방 프롬프트(bp-v4-comment) 배포 · API PRISM/GENERATE-BP-COMMENT · llmServiceKey 발급 | H13: char_count와 실제 글자수 비교 | I13: 정상 호출 | J13: LLM 자체 계산이라 차이 가능 → 정확값 필요 시 one_liner로 재계산(알려진 한계) | R13: 참고 | S13: 공통 | T13: 작업자7
A14: =IFERROR(INDEX('시나리오'!$G$5:$G$11,MATCH($T14,'시나리오'!$L$5:$L$11,0)),$T14) | B14: API-013 | C14: API | D14: ④ 자소서 특장점 | E14: P1 | F14: 정상 요약 | G14: execute API·공방 프롬프트(bp-point-summary) 배포 | H14: keyValue.body=자소서 본문으로 호출 | I14: 자소서 본문 | J14: status=ok, result.highlights 배열 반환 | S14: 공통 | T14: 작업자1
A15: =IFERROR(INDEX('시나리오'!$G$5:$G$11,MATCH($T15,'시나리오'!$L$5:$L$11,0)),$T15) | B15: API-014 | C15: API | D15: ④ 자소서 특장점 | E15: P1 | F15: 개수 4~5개 | G15: execute API·공방 프롬프트(bp-point-summary) 배포 | H15: highlights 길이 확인 | I15: 정상 body | J15: highlights 4~5개(3개 이하/6개 이상 실패) | S15: 공통 | T15: 작업자2
A16: =IFERROR(INDEX('시나리오'!$G$5:$G$11,MATCH($T16,'시나리오'!$L$5:$L$11,0)),$T16) | B16: API-015 | C16: API | D16: ④ 자소서 특장점 | E16: P2 | F16: 형식: 20자 안팎 명사구 | G16: execute API·공방 프롬프트(bp-point-summary) 배포 | H16: 각 항목 길이·종결형 확인 | I16: 정상 body | J16: 각 항목 18~25자 짧은 명사구, 명사·체언 종결('~했다'·'제목: 설명' 아님) | S16: 공통 | T16: 작업자3
A17: =IFERROR(INDEX('시나리오'!$G$5:$G$11,MATCH($T17,'시나리오'!$L$5:$L$11,0)),$T17) | B17: API-016 | C17: API | D17: ④ 자소서 특장점 | E17: P1 | F17: 가치판단 금지 | G17: execute API·공방 프롬프트(bp-point-summary) 배포 | H17: 평가어 포함 검사 | I17: 정상 body | J17: '좋다/나쁘다·강점/약점·우수/부족' 등 평가어 없음(중립 요약) | R17: hard fail | S17: 공통 | T17: 작업자4
A18: =IFERROR(INDEX('시나리오'!$G$5:$G$11,MATCH($T18,'시나리오'!$L$5:$L$11,0)),$T18) | B18: API-017 | C18: API | D18: ④ 자소서 특장점 | E18: P1 | F18: 무근거 금지 | G18: execute API·공방 프롬프트(bp-point-summary) 배포 | H18: 본문 대조 | I18: 정상 body | J18: 본문에 없는 경력·수치·사실 생성 없음, 모든 항목 본문 근거 기반 | R18: hard fail | S18: 공통 | T18: 작업자5
A19: =IFERROR(INDEX('시나리오'!$G$5:$G$11,MATCH($T19,'시나리오'!$L$5:$L$11,0)),$T19) | B19: API-018 | C19: API | D19: ④ 자소서 특장점 | E19: P2 | F19: 중복 금지 | G19: execute API·공방 프롬프트(bp-point-summary) 배포 | H19: 항목 간 의미 중복 확인 | I19: 정상 body | J19: 같은 내용 반복 항목 없음 | S19: 공통 | T19: 작업자6
A20: =IFERROR(INDEX('시나리오'!$G$5:$G$11,MATCH($T20,'시나리오'!$L$5:$L$11,0)),$T20) | B20: API-019 | C20: API | D20: ④ 자소서 특장점 | E20: P1 | F20: 금지어 미사용 | G20: execute API·공방 프롬프트(bp-point-summary) 배포 | H20: 금지어 검사 | I20: 정상 body | J20: 합격/불합격/적격/부적격/탈락 미포함 | R20: hard fail | S20: 공통 | T20: 작업자7
A21: =IFERROR(INDEX('시나리오'!$G$5:$G$11,MATCH($T21,'시나리오'!$L$5:$L$11,0)),$T21) | B21: API-020 | C21: API | D21: ④ 자소서 특장점 | E21: P2 | F21: 마크업·번호 없음 | G21: execute API·공방 프롬프트(bp-point-summary) 배포 | H21: 출력 문자열 검사 | I21: 정상 body | J21: #·##·**·- 마크업, ①②③·1. 번호 없이 순수 문장 | S21: 공통 | T21: 작업자1
A22: =IFERROR(INDEX('시나리오'!$G$5:$G$11,MATCH($T22,'시나리오'!$L$5:$L$11,0)),$T22) | B22: API-021 | C22: API | D22: ④ 자소서 특장점 | E22: P2 | F22: 입력=body만 | G22: execute API·공방 프롬프트(bp-point-summary) 배포 | H22: 입력 구성 확인 | I22: head+body 동시 전달 시도 | J22: 질문 head 미포함, 본문만으로 요약(여러 문항이면 답변 이어붙임) | S22: 공통 | T22: 작업자2
A23: =IFERROR(INDEX('시나리오'!$G$5:$G$11,MATCH($T23,'시나리오'!$L$5:$L$11,0)),$T23) | B23: API-022 | C23: API | D23: ④ 자소서 특장점 | E23: P3 | F23: 결과지 매핑 | G23: execute API·공방 프롬프트(bp-point-summary) 배포 | H23: P1 summary-bullets 매핑 확인 | I23: 정상 highlights | J23: highlights[]가 결과지 P1 요약카드 불릿에 그대로 매핑(소비측 분해 불필요) | S23: 공통 | T23: 작업자3
A24: =IFERROR(INDEX('시나리오'!$G$5:$G$11,MATCH($T24,'시나리오'!$L$5:$L$11,0)),$T24) | B24: API-023 | C24: API | D24: ② 하드스킬 추출 | E24: P1 | F24: 정상 추출 | G24: 하드스킬 추출 프롬프트(공방 extract-jd-hardskill) 배포 · JD 입력 가능 | H24: keyValue.jd_text=JD plain text로 호출 | I24: JD 본문 | J24: status=ok, required_hard_skills 5~7개 반환 | S24: 공통 | T24: 작업자4
A25: =IFERROR(INDEX('시나리오'!$G$5:$G$11,MATCH($T25,'시나리오'!$L$5:$L$11,0)),$T25) | B25: API-024 | C25: API | D25: ② 하드스킬 추출 | E25: P1 | F25: 개수 5~7개 | G25: 하드스킬 추출 프롬프트(공방 extract-jd-hardskill) 배포 · JD 입력 가능 | H25: 목록 길이 확인 | I25: 정상 JD | J25: required_hard_skills 5~7개(미만/초과 재실행) | S25: 공통 | T25: 작업자5
A26: =IFERROR(INDEX('시나리오'!$G$5:$G$11,MATCH($T26,'시나리오'!$L$5:$L$11,0)),$T26) | B26: API-025 | C26: API | D26: ② 하드스킬 추출 | E26: P1 | F26: 3범주만 | G26: 하드스킬 추출 프롬프트(공방 extract-jd-hardskill) 배포 · JD 입력 가능 | H26: category 값 확인 | I26: 정상 JD | J26: category가 tool_based/method_based/knowledge_based만(경험·산출물 유형 추출 안 함) | S26: 공통 | T26: 작업자6
A27: =IFERROR(INDEX('시나리오'!$G$5:$G$11,MATCH($T27,'시나리오'!$L$5:$L$11,0)),$T27) | B27: API-026 | C27: API | D27: ② 하드스킬 추출 | E27: P1 | F27: evidence_from_input 원문 보존 | G27: 하드스킬 추출 프롬프트(공방 extract-jd-hardskill) 배포 · JD 입력 가능 | H27: 원문 대조 | I27: 정상 JD | J27: 각 항목 evidence_from_input에 JD 원문 일부 그대로 보존(무근거 금지) | S27: 공통 | T27: 작업자7
A28: =IFERROR(INDEX('시나리오'!$G$5:$G$11,MATCH($T28,'시나리오'!$L$5:$L$11,0)),$T28) | B28: API-027 | C28: API | D28: ② 하드스킬 추출 | E28: P1 | F28: 검출 기준 동반 생성 | G28: 하드스킬 추출 프롬프트(공방 extract-jd-hardskill) 배포 · JD 입력 가능 | H28: detection_criteria 확인 | I28: 정상 JD | J28: 각 하드스킬에 detection_criteria(ⓐ인정+ⓑ배제 조건) 존재, 누락 시 보강 | S28: 공통 | T28: 작업자1
A29: =IFERROR(INDEX('시나리오'!$G$5:$G$11,MATCH($T29,'시나리오'!$L$5:$L$11,0)),$T29) | B29: API-028 | C29: API | D29: ② 하드스킬 추출 | E29: P1 | F29: Hard↔Soft 혼동 금지 | G29: 하드스킬 추출 프롬프트(공방 extract-jd-hardskill) 배포 · JD 입력 가능 | H29: 결과 검사 | I29: '성실'·'소통' 등 태도 포함 JD | J29: 소프트스킬(태도·성향) 미추출, 혼입 시 실패 | R29: hard fail | S29: 공통 | T29: 작업자2
A30: =IFERROR(INDEX('시나리오'!$G$5:$G$11,MATCH($T30,'시나리오'!$L$5:$L$11,0)),$T30) | B30: API-029 | C30: API | D30: ② 하드스킬 추출 | E30: P1 | F30: 필수 누락 시 중단 | G30: 하드스킬 추출 프롬프트(공방 extract-jd-hardskill) 배포 · JD 입력 가능 | H30: 응답 확인 | I30: job_title·핵심업무 없는 JD | J30: job_title/key_responsibilities 없으면 중단·재요청(required_competencies 없으면 진행하되 하드스킬 빌 수 있음) | S30: 공통 | T30: 작업자3
A31: =IFERROR(INDEX('시나리오'!$G$5:$G$11,MATCH($T31,'시나리오'!$L$5:$L$11,0)),$T31) | B31: API-030 | C31: API | D31: ② 하드스킬 추출 | E31: P2 | F31: 임의 추가 금지 | G31: 하드스킬 추출 프롬프트(공방 extract-jd-hardskill) 배포 · JD 입력 가능 | H31: 결과 검사 | I31: 팀·연차 미기재 JD | J31: 팀명·부서·경력연차·학력·보상·근무지·고용형태를 임의 추정·추가 안 함(미입력은 missing_information) | S31: 공통 | T31: 작업자4
A32: =IFERROR(INDEX('시나리오'!$G$5:$G$11,MATCH($T32,'시나리오'!$L$5:$L$11,0)),$T32) | B32: API-031 | C32: API | D32: ② 하드스킬 추출 | E32: P2 | F32: capability 문장화 | G32: 하드스킬 추출 프롬프트(공방 extract-jd-hardskill) 배포 · JD 입력 가능 | H32: rewritten_as_capability 확인 | I32: 정상 JD | J32: 단순 키워드가 아닌 '목적어+동사+관찰 가능 결과물' 한 문장 | S32: 공통 | T32: 작업자5
A33: =IFERROR(INDEX('시나리오'!$G$5:$G$11,MATCH($T33,'시나리오'!$L$5:$L$11,0)),$T33) | B33: API-032 | C33: API | D33: ② 하드스킬 추출 | E33: P2 | F33: 필수/우대 분류 | G33: 하드스킬 추출 프롬프트(공방 extract-jd-hardskill) 배포 · JD 입력 가능 | H33: requirement_type 확인 | I33: 우대사항 포함 JD | J33: 지원자격·필수→must_have, 우대→nice_to_have 정확 분류 | S33: 공통 | T33: 작업자6
A34: =IFERROR(INDEX('시나리오'!$G$5:$G$11,MATCH($T34,'시나리오'!$L$5:$L$11,0)),$T34) | B34: API-033 | C34: API | D34: ② 하드스킬 추출 | E34: P2 | F34: 입력 흐름(접수 업로드→매니저 plain text) | G34: 하드스킬 추출 프롬프트(공방 extract-jd-hardskill) 배포 · JD 입력 가능 | H34: 입력 경로 확인 | I34: JD 파일→텍스트 | J34: 고객사가 접수 화면에서 JD/채용공고 파일 업로드 → 운영자가 다운로드해 매니저에 plain text 직접 입력 → 추출 API 입력=plain text. 키워드 확장 없음(AI 프롬프트 매칭) | R34: 확정 2026-06-24 | S34: 공통 | T34: 작업자7
A35: =IFERROR(INDEX('시나리오'!$G$5:$G$11,MATCH($T35,'시나리오'!$L$5:$L$11,0)),$T35) | B35: API-034 | C35: API | D35: ③ 하드스킬 검출 | E35: P1 | F35: 정상 검출 | G35: COMMON/EXTRACT-EVIDENCE(공방 hardskill-extract-evidence-test, 폴백 EVALUATE) 가용 · 1단계 하드스킬+검출기준 확보 | H35: key·rubric·body로 호출 | I35: 자소서+하드스킬 목록 | J35: status=ok, result[].key별 evidence(근거문장) 반환 | S35: 공통 | T35: 작업자1
A36: =IFERROR(INDEX('시나리오'!$G$5:$G$11,MATCH($T36,'시나리오'!$L$5:$L$11,0)),$T36) | B36: API-035 | C36: API | D36: ③ 하드스킬 검출 | E36: P1 | F36: rubric inline 전달 | G36: COMMON/EXTRACT-EVIDENCE(공방 hardskill-extract-evidence-test, 폴백 EVALUATE) 가용 · 1단계 하드스킬+검출기준 확보 | H36: rubric 구성 확인 | I36: 1단계 검출기준 | J36: rubric에 모든 key의 검출 기준 포함(누락 key 없음) | S36: 공통 | T36: 작업자2
A37: =IFERROR(INDEX('시나리오'!$G$5:$G$11,MATCH($T37,'시나리오'!$L$5:$L$11,0)),$T37) | B37: API-036 | C37: API | D37: ③ 하드스킬 검출 | E37: P1 | F37: 검출/미검출 판정 | G37: COMMON/EXTRACT-EVIDENCE(공방 hardskill-extract-evidence-test, 폴백 EVALUATE) 가용 · 1단계 하드스킬+검출기준 확보 | H37: score/confidence 기준 판정 확인 | I37: 정상 호출 | J37: score 기준 검출/미검출 판정(minEvidenceItem=1이라 evidence ≥1, score 낮으면 미검출) | S37: 공통 | T37: 작업자3
A38: =IFERROR(INDEX('시나리오'!$G$5:$G$11,MATCH($T38,'시나리오'!$L$5:$L$11,0)),$T38) | B38: API-037 | C38: API | D38: ③ 하드스킬 검출 | E38: P1 | F38: 무근거 금지 | G38: COMMON/EXTRACT-EVIDENCE(공방 hardskill-extract-evidence-test, 폴백 EVALUATE) 가용 · 1단계 하드스킬+검출기준 확보 | H38: evidence 본문 대조 | I38: 정상 호출 | J38: 자소서에 실제로 있는 문장만 evidence로 반환(없는 근거 생성 없음) | R38: hard fail | S38: 공통 | T38: 작업자4
A39: =IFERROR(INDEX('시나리오'!$G$5:$G$11,MATCH($T39,'시나리오'!$L$5:$L$11,0)),$T39) | B39: API-038 | C39: API | D39: ③ 하드스킬 검출 | E39: P1 | F39: 배제 조건 적용 | G39: COMMON/EXTRACT-EVIDENCE(공방 hardskill-extract-evidence-test, 폴백 EVALUATE) 가용 · 1단계 하드스킬+검출기준 확보 | H39: 오검출 확인 | I39: 피상적·동음이의 포함 자소서 | J39: ⓑ배제 조건(피상적 언급·동음이의) 근거 불인정, 단어 일치만으로 채택 안 함 → score 낮게/미검출 | S39: 공통 | T39: 작업자5
A40: =IFERROR(INDEX('시나리오'!$G$5:$G$11,MATCH($T40,'시나리오'!$L$5:$L$11,0)),$T40) | B40: API-039 | C40: API | D40: ③ 하드스킬 검출 | E40: P2 | F40: 근거 개수 제약 | G40: COMMON/EXTRACT-EVIDENCE(공방 hardskill-extract-evidence-test, 폴백 EVALUATE) 가용 · 1단계 하드스킬+검출기준 확보 | H40: evidence 개수 확인 | I40: minEvidenceItem=1,max=5 | J40: 키별 evidence 1~5개 | S40: 공통 | T40: 작업자6
...

Sheet TC_어드민
A1: 담당 | B1: TC ID | C1: 대분류 | D1: 중분류 | E1: 우선 순위 | F1: 테스트 시나리오(케이스명) | G1: 사전조건 | H1: 테스트 절차 | I1: 입력/조건 | J1: 기대결과 | K1: QC결과 | L1: 실행일 | M1: QC담당자 | N1: 결함 내용 | O1: 심각도 | P1: 개발 수정상태 | Q1: 재확인(QC) | R1: 비고 | S1: 구분 | T1: 키(작업자)
A2: =IFERROR(INDEX('시나리오'!$G$5:$G$11,MATCH($T2,'시나리오'!$L$5:$L$11,0)),$T2) | B2: ADM-001 | C2: 어드민 | D2: 검사요청서 | E2: P1 | F2: 벌크형/단건형 전환 | G2: 검사요청서 화면 진입 | H2: 벌크형↔단건형 토글 | I2: - | J2: 선택에 따라 입력 폼이 전환되고 이전 입력이 유실되지 않음 | R2: 화면정의서 기준 확정 필요 | S2: 공통 | T2: 작업자3
A3: =IFERROR(INDEX('시나리오'!$G$5:$G$11,MATCH($T3,'시나리오'!$L$5:$L$11,0)),$T3) | B3: ADM-002 | C3: 어드민 | D3: 검사요청서 | E3: P2 | F3: 파일 추가/삭제 | G3: 화면 진입 | H3: 파일 추가 후 목록 확인, 삭제 | I3: 테스트 파일 | J3: 파일명·파일크기 표시, 삭제 시 목록에서 제거 | R3: 화면정의서 기준 확정 필요 | S3: 공통 | T3: 작업자4
A4: =IFERROR(INDEX('시나리오'!$G$5:$G$11,MATCH($T4,'시나리오'!$L$5:$L$11,0)),$T4) | B4: ADM-003 | C4: 어드민 | D4: 검사요청서 | E4: P2 | F4: 최근 검사요청서 불러오기 | G4: 이전 요청 이력 존재 | H4: 불러오기 실행 | I4: - | J4: 이전 검사요청서 내용이 폼에 채워짐 | R4: 화면정의서 기준 확정 필요 | S4: 공통 | T4: 작업자5
A5: =IFERROR(INDEX('시나리오'!$G$5:$G$11,MATCH($T5,'시나리오'!$L$5:$L$11,0)),$T5) | B5: ADM-004 | C5: 어드민 | D5: 검사요청서 | E5: P2 | F5: 임시저장 | G5: 입력 일부 작성 | H5: 임시저장 클릭 | I5: 부분 입력 | J5: 입력 내용 저장, 재진입 시 복원 | R5: 화면정의서 기준 확정 필요 | S5: 공통 | T5: 작업자6
A6: =IFERROR(INDEX('시나리오'!$G$5:$G$11,MATCH($T6,'시나리오'!$L$5:$L$11,0)),$T6) | B6: ADM-005 | C6: 어드민 | D6: 검사요청서 | E6: P1 | F6: 검사요청 제출(필수값 검증) | G6: 필수 항목 미입력 | H6: 검사요청 클릭 | I6: 필수값 누락 | J6: 필수값 누락 시 제출 차단·안내, 충족 시 정상 접수 | R6: 화면정의서 기준 확정 필요 | S6: 공통 | T6: 작업자7
A7: =IFERROR(INDEX('시나리오'!$G$5:$G$11,MATCH($T7,'시나리오'!$L$5:$L$11,0)),$T7) | B7: ADM-006 | C7: 어드민 | D7: 검사요청서 | E7: P3 | F7: 나가기(미저장 경고) | G7: 미저장 변경 존재 | H7: 나가기 클릭 | I7: - | J7: 미저장 변경 시 경고 노출 | R7: 화면정의서 기준 확정 필요 | S7: 공통 | T7: 작업자1
A8: =IFERROR(INDEX('시나리오'!$G$5:$G$11,MATCH($T8,'시나리오'!$L$5:$L$11,0)),$T8) | B8: ADM-007 | C8: 어드민 | D8: 자료 생성 | E8: P2 | F8: 자료생성 모달 오픈 | G8: 검사 요청 존재 | H8: 서류결과 자료생성 클릭 | I8: - | J8: 자료 생성 등록 모달이 열림 | R8: 화면정의서 기준 확정 필요 | S8: 공통 | T8: 작업자2
A9: =IFERROR(INDEX('시나리오'!$G$5:$G$11,MATCH($T9,'시나리오'!$L$5:$L$11,0)),$T9) | B9: ADM-008 | C9: 어드민 | D9: 자료 생성 | E9: P2 | F9: 파일 업로드 | G9: 모달 오픈 | H9: 파일 업로드 | I9: 결과 파일 | J9: 파일명 표시, 업로드 반영 | R9: 화면정의서 기준 확정 필요 | S9: 공통 | T9: 작업자3
A10: =IFERROR(INDEX('시나리오'!$G$5:$G$11,MATCH($T10,'시나리오'!$L$5:$L$11,0)),$T10) | B10: ADM-009 | C10: 어드민 | D10: 자료 생성 | E10: P2 | F10: 멀티스텝 이전/다음 | G10: 모달 오픈 | H10: 이전/다음 단계 이동 | I10: - | J10: 단계 이동 시 입력 유지, 자료생성등록 완료 | R10: 화면정의서 기준 확정 필요 | S10: 공통 | T10: 작업자4
A11: =IFERROR(INDEX('시나리오'!$G$5:$G$11,MATCH($T11,'시나리오'!$L$5:$L$11,0)),$T11) | B11: ADM-010 | C11: 어드민 | D11: 자료 생성 | E11: P3 | F11: 닫기 | G11: 모달 오픈 | H11: 닫기/× 클릭 | I11: - | J11: 모달 닫힘 | R11: 화면정의서 기준 확정 필요 | S11: 공통 | T11: 작업자5
A12: =IFERROR(INDEX('시나리오'!$G$5:$G$11,MATCH($T12,'시나리오'!$L$5:$L$11,0)),$T12) | B12: ADM-011 | C12: 어드민 | D12: 근거요약 QC | E12: P1 | F12: 결함검사·항목 표시 | G12: 근거요약관리 모달 진입 | H12: 항목 확인 | I12: - | J12: 메트릭별 결함검사·등급·근거문장이 표시됨 | R12: 화면정의서 기준 확정 필요 | S12: 공통 | T12: 작업자6
A13: =IFERROR(INDEX('시나리오'!$G$5:$G$11,MATCH($T13,'시나리오'!$L$5:$L$11,0)),$T13) | B13: ADM-012 | C13: 어드민 | D13: 근거요약 QC | E13: P1 | F13: 재생성 | G13: 항목 표시 | H13: 메트릭 재생성 클릭 | I13: - | J13: 해당 메트릭 코멘트/근거가 재생성되어 갱신 | R13: 화면정의서 기준 확정 필요 | S13: 공통 | T13: 작업자7
... A57: =IFERROR(INDEX('시나리오'!$G$5:$G$11,MATCH($T57,'시나리오'!$L$5:$L$11,0)),$T57) | B57: ADM-056 | C57: 어드민 | D57: 프리즘워크-다운로드 설정 | E57: P1 | F57: 통합본문 옵션 동작 | G57: 다운로드 설정 · 복수 검사 선택됨 | H57: 통합본문 ON/OFF 선택 후 다운로드 | I57: - | J57: ON 시 선택 검사 출처가 자소서 1부에 통합되고 개별 검사 본문은 제거 / OFF 시 개별 본문 포함, 통합본문 없음 | R57: 화면정의서 기준 확정 필요 | S57: 공통 | T57: 작업자2
